2025-04-19 22:33:01,506 INFO    MainThread:32124 [wandb_init.py:setup_run_log_directory():662] Logging user logs to d:\Jamie\IIT Madras\Semester II_1st Year_2024-25\DA6401 Introduction to Deep Learning\Assignments\2\Github\wandb\run-20250419_223301-u838qsct\logs\debug.log
2025-04-19 22:33:01,506 INFO    MainThread:32124 [wandb_init.py:setup_run_log_directory():663] Logging internal logs to d:\Jamie\IIT Madras\Semester II_1st Year_2024-25\DA6401 Introduction to Deep Learning\Assignments\2\Github\wandb\run-20250419_223301-u838qsct\logs\debug-internal.log
2025-04-19 22:33:01,507 INFO    MainThread:32124 [wandb_init.py:init():781] calling init triggers
2025-04-19 22:33:01,507 INFO    MainThread:32124 [wandb_init.py:init():786] wandb.init called with sweep_config: {}
config: {'num_filters': [8, 16, 32, 64, 128], 'kernel_size': 3, 'activation': 'silu', 'use_batchnorm': True, 'dropout': 0.3, 'dense_neurons': 256, 'num_classes': 10, 'lr': 0.00107, 'batch_size': 64, 'augment': False, 'epochs': 10, '_wandb': {}}
2025-04-19 22:33:01,507 INFO    MainThread:32124 [wandb_init.py:init():809] starting backend
2025-04-19 22:33:01,507 INFO    MainThread:32124 [wandb_init.py:init():813] sending inform_init request
2025-04-19 22:33:01,510 INFO    MainThread:32124 [backend.py:_multiprocessing_setup():101] multiprocessing start_methods=spawn, using: spawn
2025-04-19 22:33:01,510 INFO    MainThread:32124 [wandb_init.py:init():823] backend started and connected
2025-04-19 22:33:01,513 INFO    MainThread:32124 [wandb_run.py:_label_probe_notebook():1267] probe notebook
2025-04-19 22:33:01,533 INFO    MainThread:32124 [wandb_init.py:init():915] updated telemetry
2025-04-19 22:33:01,628 INFO    MainThread:32124 [wandb_init.py:init():939] communicating run to backend with 90.0 second timeout
2025-04-19 22:33:28,218 INFO    Thread-16 :32124 [retry.py:__call__():175] [no run ID] Retry attempt failed:
Traceback (most recent call last):
  File "d:\Jamie\miniconda3\envs\env2\lib\site-packages\urllib3\connection.py", line 174, in _new_conn
    conn = connection.create_connection(
  File "d:\Jamie\miniconda3\envs\env2\lib\site-packages\urllib3\util\connection.py", line 95, in create_connection
    raise err
  File "d:\Jamie\miniconda3\envs\env2\lib\site-packages\urllib3\util\connection.py", line 85, in create_connection
    sock.connect(sa)
ConnectionAbortedError: [WinError 10053] An established connection was aborted by the software in your host machine

During handling of the above exception, another exception occurred:

Traceback (most recent call last):
  File "d:\Jamie\miniconda3\envs\env2\lib\site-packages\urllib3\connectionpool.py", line 716, in urlopen
    httplib_response = self._make_request(
  File "d:\Jamie\miniconda3\envs\env2\lib\site-packages\urllib3\connectionpool.py", line 404, in _make_request
    self._validate_conn(conn)
  File "d:\Jamie\miniconda3\envs\env2\lib\site-packages\urllib3\connectionpool.py", line 1061, in _validate_conn
    conn.connect()
  File "d:\Jamie\miniconda3\envs\env2\lib\site-packages\urllib3\connection.py", line 363, in connect
    self.sock = conn = self._new_conn()
  File "d:\Jamie\miniconda3\envs\env2\lib\site-packages\urllib3\connection.py", line 186, in _new_conn
    raise NewConnectionError(
urllib3.exceptions.NewConnectionError: <urllib3.connection.HTTPSConnection object at 0x000002970D0E22B0>: Failed to establish a new connection: [WinError 10053] An established connection was aborted by the software in your host machine

During handling of the above exception, another exception occurred:

Traceback (most recent call last):
  File "d:\Jamie\miniconda3\envs\env2\lib\site-packages\requests\adapters.py", line 667, in send
    resp = conn.urlopen(
  File "d:\Jamie\miniconda3\envs\env2\lib\site-packages\urllib3\connectionpool.py", line 802, in urlopen
    retries = retries.increment(
  File "d:\Jamie\miniconda3\envs\env2\lib\site-packages\urllib3\util\retry.py", line 594, in increment
    raise MaxRetryError(_pool, url, error or ResponseError(cause))
urllib3.exceptions.MaxRetryError: HTTPSConnectionPool(host='api.wandb.ai', port=443): Max retries exceeded with url: /graphql (Caused by NewConnectionError('<urllib3.connection.HTTPSConnection object at 0x000002970D0E22B0>: Failed to establish a new connection: [WinError 10053] An established connection was aborted by the software in your host machine'))

During handling of the above exception, another exception occurred:

Traceback (most recent call last):
  File "d:\Jamie\miniconda3\envs\env2\lib\site-packages\wandb\sdk\lib\retry.py", line 134, in __call__
    result = self._call_fn(*args, **kwargs)
  File "d:\Jamie\miniconda3\envs\env2\lib\site-packages\wandb\sdk\internal\internal_api.py", line 402, in execute
    return self.client.execute(*args, **kwargs)  # type: ignore
  File "d:\Jamie\miniconda3\envs\env2\lib\site-packages\wandb\vendor\gql-0.2.0\wandb_gql\client.py", line 52, in execute
    result = self._get_result(document, *args, **kwargs)
  File "d:\Jamie\miniconda3\envs\env2\lib\site-packages\wandb\vendor\gql-0.2.0\wandb_gql\client.py", line 60, in _get_result
    return self.transport.execute(document, *args, **kwargs)
  File "d:\Jamie\miniconda3\envs\env2\lib\site-packages\wandb\sdk\lib\gql_request.py", line 58, in execute
    request = self.session.post(self.url, **post_args)
  File "d:\Jamie\miniconda3\envs\env2\lib\site-packages\requests\sessions.py", line 637, in post
    return self.request("POST", url, data=data, json=json, **kwargs)
  File "d:\Jamie\miniconda3\envs\env2\lib\site-packages\requests\sessions.py", line 589, in request
    resp = self.send(prep, **send_kwargs)
  File "d:\Jamie\miniconda3\envs\env2\lib\site-packages\requests\sessions.py", line 703, in send
    r = adapter.send(request, **kwargs)
  File "d:\Jamie\miniconda3\envs\env2\lib\site-packages\requests\adapters.py", line 700, in send
    raise ConnectionError(e, request=request)
requests.exceptions.ConnectionError: HTTPSConnectionPool(host='api.wandb.ai', port=443): Max retries exceeded with url: /graphql (Caused by NewConnectionError('<urllib3.connection.HTTPSConnection object at 0x000002970D0E22B0>: Failed to establish a new connection: [WinError 10053] An established connection was aborted by the software in your host machine'))
2025-04-19 22:33:28,219 INFO    Thread-17 :32124 [retry.py:__call__():175] [no run ID] Retry attempt failed:
Traceback (most recent call last):
  File "d:\Jamie\miniconda3\envs\env2\lib\site-packages\urllib3\connection.py", line 174, in _new_conn
    conn = connection.create_connection(
  File "d:\Jamie\miniconda3\envs\env2\lib\site-packages\urllib3\util\connection.py", line 95, in create_connection
    raise err
  File "d:\Jamie\miniconda3\envs\env2\lib\site-packages\urllib3\util\connection.py", line 85, in create_connection
    sock.connect(sa)
ConnectionAbortedError: [WinError 10053] An established connection was aborted by the software in your host machine

During handling of the above exception, another exception occurred:

Traceback (most recent call last):
  File "d:\Jamie\miniconda3\envs\env2\lib\site-packages\urllib3\connectionpool.py", line 716, in urlopen
    httplib_response = self._make_request(
  File "d:\Jamie\miniconda3\envs\env2\lib\site-packages\urllib3\connectionpool.py", line 404, in _make_request
    self._validate_conn(conn)
  File "d:\Jamie\miniconda3\envs\env2\lib\site-packages\urllib3\connectionpool.py", line 1061, in _validate_conn
    conn.connect()
  File "d:\Jamie\miniconda3\envs\env2\lib\site-packages\urllib3\connection.py", line 363, in connect
    self.sock = conn = self._new_conn()
  File "d:\Jamie\miniconda3\envs\env2\lib\site-packages\urllib3\connection.py", line 186, in _new_conn
    raise NewConnectionError(
urllib3.exceptions.NewConnectionError: <urllib3.connection.HTTPSConnection object at 0x000002970D3C42E0>: Failed to establish a new connection: [WinError 10053] An established connection was aborted by the software in your host machine

During handling of the above exception, another exception occurred:

Traceback (most recent call last):
  File "d:\Jamie\miniconda3\envs\env2\lib\site-packages\requests\adapters.py", line 667, in send
    resp = conn.urlopen(
  File "d:\Jamie\miniconda3\envs\env2\lib\site-packages\urllib3\connectionpool.py", line 802, in urlopen
    retries = retries.increment(
  File "d:\Jamie\miniconda3\envs\env2\lib\site-packages\urllib3\util\retry.py", line 594, in increment
    raise MaxRetryError(_pool, url, error or ResponseError(cause))
urllib3.exceptions.MaxRetryError: HTTPSConnectionPool(host='api.wandb.ai', port=443): Max retries exceeded with url: /graphql (Caused by NewConnectionError('<urllib3.connection.HTTPSConnection object at 0x000002970D3C42E0>: Failed to establish a new connection: [WinError 10053] An established connection was aborted by the software in your host machine'))

During handling of the above exception, another exception occurred:

Traceback (most recent call last):
  File "d:\Jamie\miniconda3\envs\env2\lib\site-packages\wandb\sdk\lib\retry.py", line 134, in __call__
    result = self._call_fn(*args, **kwargs)
  File "d:\Jamie\miniconda3\envs\env2\lib\site-packages\wandb\sdk\internal\internal_api.py", line 402, in execute
    return self.client.execute(*args, **kwargs)  # type: ignore
  File "d:\Jamie\miniconda3\envs\env2\lib\site-packages\wandb\vendor\gql-0.2.0\wandb_gql\client.py", line 52, in execute
    result = self._get_result(document, *args, **kwargs)
  File "d:\Jamie\miniconda3\envs\env2\lib\site-packages\wandb\vendor\gql-0.2.0\wandb_gql\client.py", line 60, in _get_result
    return self.transport.execute(document, *args, **kwargs)
  File "d:\Jamie\miniconda3\envs\env2\lib\site-packages\wandb\sdk\lib\gql_request.py", line 58, in execute
    request = self.session.post(self.url, **post_args)
  File "d:\Jamie\miniconda3\envs\env2\lib\site-packages\requests\sessions.py", line 637, in post
    return self.request("POST", url, data=data, json=json, **kwargs)
  File "d:\Jamie\miniconda3\envs\env2\lib\site-packages\requests\sessions.py", line 589, in request
    resp = self.send(prep, **send_kwargs)
  File "d:\Jamie\miniconda3\envs\env2\lib\site-packages\requests\sessions.py", line 703, in send
    r = adapter.send(request, **kwargs)
  File "d:\Jamie\miniconda3\envs\env2\lib\site-packages\requests\adapters.py", line 700, in send
    raise ConnectionError(e, request=request)
requests.exceptions.ConnectionError: HTTPSConnectionPool(host='api.wandb.ai', port=443): Max retries exceeded with url: /graphql (Caused by NewConnectionError('<urllib3.connection.HTTPSConnection object at 0x000002970D3C42E0>: Failed to establish a new connection: [WinError 10053] An established connection was aborted by the software in your host machine'))
